*** Reading local file: /root/airflow/logs/dag_id=load_data_to_redshift/run_id=manual__2023-06-11T11:01:25.343743+00:00/task_id=create_table/attempt=1.log
[2023-06-11, 16:31:29 IST] {taskinstance.py:1159} INFO - Dependencies all met for <TaskInstance: load_data_to_redshift.create_table manual__2023-06-11T11:01:25.343743+00:00 [queued]>
[2023-06-11, 16:31:30 IST] {taskinstance.py:1159} INFO - Dependencies all met for <TaskInstance: load_data_to_redshift.create_table manual__2023-06-11T11:01:25.343743+00:00 [queued]>
[2023-06-11, 16:31:30 IST] {taskinstance.py:1356} INFO - 
--------------------------------------------------------------------------------
[2023-06-11, 16:31:30 IST] {taskinstance.py:1357} INFO - Starting attempt 1 of 1
[2023-06-11, 16:31:30 IST] {taskinstance.py:1358} INFO - 
--------------------------------------------------------------------------------
[2023-06-11, 16:31:30 IST] {taskinstance.py:1377} INFO - Executing <Task(PostgresOperator): create_table> on 2023-06-11 11:01:25.343743+00:00
[2023-06-11, 16:31:30 IST] {standard_task_runner.py:52} INFO - Started process 18043 to run task
[2023-06-11, 16:31:30 IST] {standard_task_runner.py:79} INFO - Running: ['***', 'tasks', 'run', 'load_data_to_redshift', 'create_table', 'manual__2023-06-11T11:01:25.343743+00:00', '--job-id', '4', '--raw', '--subdir', 'DAGS_FOLDER/cd0031-automate-data-pipelines/lesson-3-***-and-aws/starter/l3_e4_s3_to_redshift.py', '--cfg-path', '/tmp/tmp89ekaoer', '--error-file', '/tmp/tmp1n5i1x1s']
[2023-06-11, 16:31:30 IST] {standard_task_runner.py:80} INFO - Job 4: Subtask create_table
[2023-06-11, 16:31:30 IST] {task_command.py:370} INFO - Running <TaskInstance: load_data_to_redshift.create_table manual__2023-06-11T11:01:25.343743+00:00 [running]> on host 8a1f50169dcda5619dd3fa088d9950ce380ce77d-7947bf4cdc-b5kwm
[2023-06-11, 16:31:31 IST] {taskinstance.py:1571} INFO - Exporting the following env vars:
AIRFLOW_CTX_DAG_OWNER=Airflow
AIRFLOW_CTX_DAG_ID=load_data_to_redshift
AIRFLOW_CTX_TASK_ID=create_table
AIRFLOW_CTX_EXECUTION_DATE=2023-06-11T11:01:25.343743+00:00
AIRFLOW_CTX_TRY_NUMBER=1
AIRFLOW_CTX_DAG_RUN_ID=manual__2023-06-11T11:01:25.343743+00:00
[2023-06-11, 16:31:31 IST] {sql.py:262} INFO - Executing: 
CREATE TABLE IF NOT EXISTS trips (
trip_id INTEGER NOT NULL,
start_time TIMESTAMP NOT NULL,
end_time TIMESTAMP NOT NULL,
bikeid INTEGER NOT NULL,
tripduration DECIMAL(16,2) NOT NULL,
from_station_id INTEGER NOT NULL,
from_station_name VARCHAR(100) NOT NULL,
to_station_id INTEGER NOT NULL,
to_station_name VARCHAR(100) NOT NULL,
usertype VARCHAR(20),
gender VARCHAR(6),
birthyear INTEGER,
PRIMARY KEY(trip_id))
DISTSTYLE ALL;
[2023-06-11, 16:31:31 IST] {base.py:68} INFO - Using connection ID 'redshift' for task execution.
[2023-06-11, 16:31:32 IST] {base.py:68} INFO - Using connection ID 'redshift' for task execution.
[2023-06-11, 16:31:34 IST] {taskinstance.py:1889} ERROR - Task failed with exception
Traceback (most recent call last):
  File "/usr/local/lib/python3.7/dist-packages/redshift_connector/core.py", line 585, in __init__
    self._usock.connect((host, port))
socket.gaierror: [Errno -2] Name or service not known

During handling of the above exception, another exception occurred:

Traceback (most recent call last):
  File "/usr/local/lib/python3.7/dist-packages/airflow/providers/common/sql/operators/sql.py", line 274, in execute
    **extra_kwargs,
  File "/usr/local/lib/python3.7/dist-packages/airflow/providers/common/sql/hooks/sql.py", line 342, in run
    with closing(self.get_conn()) as conn:
  File "/usr/local/lib/python3.7/dist-packages/airflow/providers/amazon/aws/hooks/redshift_sql.py", line 129, in get_conn
    return redshift_connector.connect(**conn_kwargs)
  File "/usr/local/lib/python3.7/dist-packages/redshift_connector/__init__.py", line 360, in connect
    numeric_to_float=info.numeric_to_float,
  File "/usr/local/lib/python3.7/dist-packages/redshift_connector/core.py", line 632, in __init__
    raise InterfaceError("communication error", e)
redshift_connector.error.InterfaceError: ('communication error', gaierror(-2, 'Name or service not known'))
[2023-06-11, 16:31:34 IST] {taskinstance.py:1400} INFO - Marking task as FAILED. dag_id=load_data_to_redshift, task_id=create_table, execution_date=20230611T110125, start_date=20230611T110130, end_date=20230611T110134
[2023-06-11, 16:31:34 IST] {standard_task_runner.py:97} ERROR - Failed to execute job 4 for task create_table (('communication error', gaierror(-2, 'Name or service not known')); 18043)
[2023-06-11, 16:31:35 IST] {local_task_job.py:156} INFO - Task exited with return code 1
[2023-06-11, 16:31:35 IST] {local_task_job.py:273} INFO - 0 downstream tasks scheduled from follow-on schedule check